Workbook
Name rl_code: 'Rules'!$A$2:$A$22
Name rl_name: 'Rules'!$B$2:$B$22
Name rl_currency: 'Rules'!$C$2:$C$22
Name rl_unit: 'Rules'!$D$2:$D$22
Name rl_curdec: 'Rules'!$E$2:$E$22
Name rl_tdec: 'Rules'!$F$2:$F$22
Name rl_eq_gy: 'Rules'!$G$2:$G$22
Name rl_eq_q: 'Rules'!$H$2:$H$22
Name rl_hours: 'Rules'!$I$2:$I$22
Name pt_id: 'Points'!$A$2:$A$124
Name pt_tso: 'Points'!$B$2:$B$124
Name pt_tso_name: 'Points'!$C$2:$C$124
Name pt_direction: 'Points'!$D$2:$D$124
Name pt_eic: 'Points'!$E$2:$E$124
Name pt_name: 'Points'!$F$2:$F$124
Name pt_captype: 'Points'!$G$2:$G$124
Name pt_currency: 'Points'!$H$2:$H$124
Name pt_unit: 'Points'!$I$2:$I$124
Name pt_frow: 'Points'!$J$2:$J$124
Name pt_count: 'Points'!$K$2:$K$124
Name pt_first_gy: 'Points'!$L$2:$L$124
Name tr_header: 'Tariffs'!$G$1:$AI$1
Name lst_booking: 'Lists'!$A$2:$A$4
Name lst_instrument: 'Lists'!$B$2:$B$5
Name lst_unit: 'Lists'!$C$2:$C$3
Name lst_tso_name: 'Lists'!$E$2:$E$22
Name lst_tso_start: 'Lists'!$G$2:$G$22
Name lst_tso_count: 'Lists'!$H$2:$H$22
Name lst_label: 'Lists'!$J$1:$J$167
Name lst_id1: 'Lists'!$K$1:$K$167
Name lst_id2: 'Lists'!$L$1:$L$167
Name lst_heading: 'Lists'!$M$1:$M$167
Name lst_rate_cur: 'Lists'!$O$2:$O$5
Name c_booking_ok: 'Calc'!$B$2
Name c_bundle: 'Calc'!$B$3
Name c_single: 'Calc'!$B$4
Name c_lng: 'Calc'!$B$5
Name c_tso_row: 'Calc'!$B$6
Name c_tso_ok: 'Calc'!$B$7
Name c_list_start: 'Calc'!$B$8
Name c_list_count: 'Calc'!$B$9
Name dv_points: OFFSET(Lists!$J$1,c_list_start-1,0,MAX(1,c_list_count),1)
Name c_point_pos: 'Calc'!$B$10
Name c_point_ok: 'Calc'!$B$11
Name c_label_row: 'Calc'!$B$12
Name c_id1: 'Calc'!$B$13
Name c_id2: 'Calc'!$B$14
Name c_heading_label: 'Calc'!$B$15
Name c_inst: 'Calc'!$B$16
Name c_today_gy: 'Calc'!$B$17
Name c_last_gy: 'Calc'!$B$18
Name c_first_gy: 'Calc'!$B$19
Name c_n_gy: 'Calc'!$B$20
Name c_period_count: 'Calc'!$B$21
Name dv_periods: OFFSET(Calc!$D$2,0,0,MAX(1,MIN(276,c_period_count)),1)
Name c_period_pos: 'Calc'!$B$22
Name c_day_ok: 'Calc'!$B$23
Name c_period_ok: 'Calc'!$B$24
Name c_py: 'Calc'!$B$25
Name c_pq: 'Calc'!$B$26

Sheet Calculator
A1: Capacity Fee Calculator
A2: Built from tariffs_real.xlsx on 2026-10-30. Fill in the yellow cells.
A4: Booking type | B4: Bundled
A5: TSO | B5: FGSZ | D5: =IF(c_single,"","Only used for Single side")
A6: =IF(c_bundle,"Bundled point",IF(c_lng,"LNG terminal","Network point")) | B6: Mosonmagyaróvár AT>HU (Gas Connect Austria + FGSZ)
A7: Product instrument | B7: Quarter
A8: Period | B8: 2026 Q4 | D8: =IF(c_inst=4,"Not used for a day: enter the day below","")
A9: Day | B9: 46361 | D9: =IF(c_inst=4,"","Only used for the Day instrument")
A10: Requested capacity | C10: kWh/h
A12: =c_msg
A13: =c_heading
A15: =IF(sa_show,sa_heading,"")
A16: =IF(sa_show,"TSO","") | B16: =IF(sa_show,sa_tso_name,"") | C16: =IF(sa_show,"Direction","") | D16: =IF(sa_show,sa_direction,"")
A17: =IF(sa_show,"Capacity ("&sa_unit&")","") | B17: =IF(sa_show,sa_capacity,"")
A18: =IF(sa_show,"Price ("&sa_colname&", "&sa_currency&" per "&sa_unit&")","") | B18: =IF(sa_show,sa_price_text,"")
A19: =IF(sa_show,"Total cost ("&sa_currency&")","") | B19: =IF(sa_show,sa_total,"")
A20: =IF(sa_show,"Tariff used","") | B20: =IF(sa_show,sa_tariff_used,"")
A21: =IF(sa_show,"All amounts are in "&sa_currency&"; the total is rounded to "&IF(sa_curdec=0,"whole forints","cents")&".","")
A22: =IF(AND(sa_show,sa_tdec<>""),sa_tso_name&" bills its tariff rounded to "&sa_tdec&" decimals.","")
A23: =IF(AND(sa_show,sa_captype="Interruptible"),"This point has no Firm tariff, so Interruptible capacity is priced; the TSO can interrupt it.","")
A24: =IF(sa_show,IF(c_bundle,"Monthly invoice ("&sa_tso_name&")","Monthly invoice"),"")
A25: =IF(AND(sa_show,sa_equal),sa_tso_name&" invoices each month as "&IF(c_inst=1,"1/12 of the gas year","1/3 of the quarter")&" at the tariff valid in it, whatever the month's number of days.","")
A26: =IF(sa_show,"Month","") | B26: =IF(sa_show,"Days","") | C26: =IF(sa_show,"Amount ("&sa_currency&")","")
A27: =IF(AND(sa_show,INDEX(sa_m_present,1)=1),INDEX(sa_m_label,1),"") | B27: =IF(AND(sa_show,INDEX(sa_m_present,1)=1),INDEX(sa_m_days,1),"") | C27: =IF(AND(sa_show,INDEX(sa_m_present,1)=1),INDEX(sa_m_amount,1),"")
A28: =IF(AND(sa_show,INDEX(sa_m_present,2)=1),INDEX(sa_m_label,2),"") | B28: =IF(AND(sa_show,INDEX(sa_m_present,2)=1),INDEX(sa_m_days,2),"") | C28: =IF(AND(sa_show,INDEX(sa_m_present,2)=1),INDEX(sa_m_amount,2),"")
A29: =IF(AND(sa_show,INDEX(sa_m_present,3)=1),INDEX(sa_m_label,3),"") | B29: =IF(AND(sa_show,INDEX(sa_m_present,3)=1),INDEX(sa_m_days,3),"") | C29: =IF(AND(sa_show,INDEX(sa_m_present,3)=1),INDEX(sa_m_amount,3),"")
A30: =IF(AND(sa_show,INDEX(sa_m_present,4)=1),INDEX(sa_m_label,4),"") | B30: =IF(AND(sa_show,INDEX(sa_m_present,4)=1),INDEX(sa_m_days,4),"") | C30: =IF(AND(sa_show,INDEX(sa_m_present,4)=1),INDEX(sa_m_amount,4),"")
A31: =IF(AND(sa_show,INDEX(sa_m_present,5)=1),INDEX(sa_m_label,5),"") | B31: =IF(AND(sa_show,INDEX(sa_m_present,5)=1),INDEX(sa_m_days,5),"") | C31: =IF(AND(sa_show,INDEX(sa_m_present,5)=1),INDEX(sa_m_amount,5),"")
A32: =IF(AND(sa_show,INDEX(sa_m_present,6)=1),INDEX(sa_m_label,6),"") | B32: =IF(AND(sa_show,INDEX(sa_m_present,6)=1),INDEX(sa_m_days,6),"") | C32: =IF(AND(sa_show,INDEX(sa_m_present,6)=1),INDEX(sa_m_amount,6),"")
A33: =IF(AND(sa_show,INDEX(sa_m_present,7)=1),INDEX(sa_m_label,7),"") | B33: =IF(AND(sa_show,INDEX(sa_m_present,7)=1),INDEX(sa_m_days,7),"") | C33: =IF(AND(sa_show,INDEX(sa_m_present,7)=1),INDEX(sa_m_amount,7),"")
A34: =IF(AND(sa_show,INDEX(sa_m_present,8)=1),INDEX(sa_m_label,8),"") | B34: =IF(AND(sa_show,INDEX(sa_m_present,8)=1),INDEX(sa_m_days,8),"") | C34: =IF(AND(sa_show,INDEX(sa_m_present,8)=1),INDEX(sa_m_amount,8),"")
A35: =IF(AND(sa_show,INDEX(sa_m_present,9)=1),INDEX(sa_m_label,9),"") | B35: =IF(AND(sa_show,INDEX(sa_m_present,9)=1),INDEX(sa_m_days,9),"") | C35: =IF(AND(sa_show,INDEX(sa_m_present,9)=1),INDEX(sa_m_amount,9),"")
A36: =IF(AND(sa_show,INDEX(sa_m_present,10)=1),INDEX(sa_m_label,10),"") | B36: =IF(AND(sa_show,INDEX(sa_m_present,10)=1),INDEX(sa_m_days,10),"") | C36: =IF(AND(sa_show,INDEX(sa_m_present,10)=1),INDEX(sa_m_amount,10),"")
A37: =IF(AND(sa_show,INDEX(sa_m_present,11)=1),INDEX(sa_m_label,11),"") | B37: =IF(AND(sa_show,INDEX(sa_m_present,11)=1),INDEX(sa_m_days,11),"") | C37: =IF(AND(sa_show,INDEX(sa_m_present,11)=1),INDEX(sa_m_amount,11),"")
A38: =IF(AND(sa_show,INDEX(sa_m_present,12)=1),INDEX(sa_m_label,12),"") | B38: =IF(AND(sa_show,INDEX(sa_m_present,12)=1),INDEX(sa_m_days,12),"") | C38: =IF(AND(sa_show,INDEX(sa_m_present,12)=1),INDEX(sa_m_amount,12),"")
A39: =IF(sa_show,"Total","") | B39: =IF(sa_show,sa_pdays,"") | C39: =IF(sa_show,sa_total,"")
A41: =IF(sb_show,sb_heading,"")
A42: =IF(sb_show,"TSO","") | B42: =IF(sb_show,sb_tso_name,"") | C42: =IF(sb_show,"Direction","") | D42: =IF(sb_show,sb_direction,"")
A43: =IF(sb_show,"Capacity ("&sb_unit&")","") | B43: =IF(sb_show,sb_capacity,"")
A44: =IF(sb_show,"Price ("&sb_colname&", "&sb_currency&" per "&sb_unit&")","") | B44: =IF(sb_show,sb_price_text,"")
...

Sheet Calc
A1: Name | B1: Value | D1: Period list
A2: c_booking_ok | B2: =ISNUMBER(MATCH(in_booking,lst_booking,0)) | D2: =IF(1>c_period_count,"",IF(c_inst=1,(c_first_gy+0)&"/"&RIGHT(c_first_gy+1,2),IF(c_inst=2,(c_first_gy+INT(0/4))&" Q"&(MOD(0,4)+1),(c_first_gy+INT(0/12))&"-"&RIGHT("0"&(MOD(0,12)+1),2))))
A3: c_bundle | B3: =in_booking="Bundled" | D3: =IF(2>c_period_count,"",IF(c_inst=1,(c_first_gy+1)&"/"&RIGHT(c_first_gy+2,2),IF(c_inst=2,(c_first_gy+INT(1/4))&" Q"&(MOD(1,4)+1),(c_first_gy+INT(1/12))&"-"&RIGHT("0"&(MOD(1,12)+1),2))))
A4: c_single | B4: =in_booking="Single side" | D4: =IF(3>c_period_count,"",IF(c_inst=1,(c_first_gy+2)&"/"&RIGHT(c_first_gy+3,2),IF(c_inst=2,(c_first_gy+INT(2/4))&" Q"&(MOD(2,4)+1),(c_first_gy+INT(2/12))&"-"&RIGHT("0"&(MOD(2,12)+1),2))))
A5: c_lng | B5: =in_booking="LNG entry" | D5: =IF(4>c_period_count,"",IF(c_inst=1,(c_first_gy+3)&"/"&RIGHT(c_first_gy+4,2),IF(c_inst=2,(c_first_gy+INT(3/4))&" Q"&(MOD(3,4)+1),(c_first_gy+INT(3/12))&"-"&RIGHT("0"&(MOD(3,12)+1),2))))
A6: c_tso_row | B6: =IFERROR(MATCH(in_tso,lst_tso_name,0),0) | D6: =IF(5>c_period_count,"",IF(c_inst=1,(c_first_gy+4)&"/"&RIGHT(c_first_gy+5,2),IF(c_inst=2,(c_first_gy+INT(4/4))&" Q"&(MOD(4,4)+1),(c_first_gy+INT(4/12))&"-"&RIGHT("0"&(MOD(4,12)+1),2))))
A7: c_tso_ok | B7: =OR(NOT(c_single),c_tso_row>0) | D7: =IF(6>c_period_count,"",IF(c_inst=1,(c_first_gy+5)&"/"&RIGHT(c_first_gy+6,2),IF(c_inst=2,(c_first_gy+INT(5/4))&" Q"&(MOD(5,4)+1),(c_first_gy+INT(5/12))&"-"&RIGHT("0"&(MOD(5,12)+1),2))))
A8: c_list_start | B8: =IF(c_bundle,2,IF(c_lng,45,IF(c_tso_row>0,INDEX(lst_tso_start,c_tso_row),1))) | D8: =IF(7>c_period_count,"",IF(c_inst=1,(c_first_gy+6)&"/"&RIGHT(c_first_gy+7,2),IF(c_inst=2,(c_first_gy+INT(6/4))&" Q"&(MOD(6,4)+1),(c_first_gy+INT(6/12))&"-"&RIGHT("0"&(MOD(6,12)+1),2))))
A9: c_list_count | B9: =IF(c_bundle,43,IF(c_lng,14,IF(c_tso_row>0,INDEX(lst_tso_count,c_tso_row),1))) | D9: =IF(8>c_period_count,"",IF(c_inst=1,(c_first_gy+7)&"/"&RIGHT(c_first_gy+8,2),IF(c_inst=2,(c_first_gy+INT(7/4))&" Q"&(MOD(7,4)+1),(c_first_gy+INT(7/12))&"-"&RIGHT("0"&(MOD(7,12)+1),2))))
A10: c_point_pos | B10: =IF(AND(c_booking_ok,c_tso_ok),IFERROR(MATCH(in_point,dv_points,0),0),0) | D10: =IF(9>c_period_count,"",IF(c_inst=1,(c_first_gy+8)&"/"&RIGHT(c_first_gy+9,2),IF(c_inst=2,(c_first_gy+INT(8/4))&" Q"&(MOD(8,4)+1),(c_first_gy+INT(8/12))&"-"&RIGHT("0"&(MOD(8,12)+1),2))))
A11: c_point_ok | B11: =c_point_pos>0 | D11: =IF(10>c_period_count,"",IF(c_inst=1,(c_first_gy+9)&"/"&RIGHT(c_first_gy+10,2),IF(c_inst=2,(c_first_gy+INT(9/4))&" Q"&(MOD(9,4)+1),(c_first_gy+INT(9/12))&"-"&RIGHT("0"&(MOD(9,12)+1),2))))
A12: c_label_row | B12: =c_list_start+c_point_pos-1 | D12: =IF(11>c_period_count,"",IF(c_inst=1,(c_first_gy+10)&"/"&RIGHT(c_first_gy+11,2),IF(c_inst=2,(c_first_gy+INT(10/4))&" Q"&(MOD(10,4)+1),(c_first_gy+INT(10/12))&"-"&RIGHT("0"&(MOD(10,12)+1),2))))
A13: c_id1 | B13: =IF(c_point_ok,INDEX(lst_id1,c_label_row),"") | D13: =IF(12>c_period_count,"",IF(c_inst=1,(c_first_gy+11)&"/"&RIGHT(c_first_gy+12,2),IF(c_inst=2,(c_first_gy+INT(11/4))&" Q"&(MOD(11,4)+1),(c_first_gy+INT(11/12))&"-"&RIGHT("0"&(MOD(11,12)+1),2))))
A14: c_id2 | B14: =IF(AND(c_point_ok,c_bundle),INDEX(lst_id2,c_label_row),"") | D14: =IF(13>c_period_count,"",IF(c_inst=1,(c_first_gy+12)&"/"&RIGHT(c_first_gy+13,2),IF(c_inst=2,(c_first_gy+INT(12/4))&" Q"&(MOD(12,4)+1),(c_first_gy+INT(12/12))&"-"&RIGHT("0"&(MOD(12,12)+1),2))))
A15: c_heading_label | B15: =IF(c_point_ok,INDEX(lst_heading,c_label_row),"") | D15: =IF(14>c_period_count,"",IF(c_inst=1,(c_first_gy+13)&"/"&RIGHT(c_first_gy+14,2),IF(c_inst=2,(c_first_gy+INT(13/4))&" Q"&(MOD(13,4)+1),(c_first_gy+INT(13/12))&"-"&RIGHT("0"&(MOD(13,12)+1),2))))
A16: c_inst | B16: =IFERROR(MATCH(in_instrument,lst_instrument,0),0) | D16: =IF(15>c_period_count,"",IF(c_inst=1,(c_first_gy+14)&"/"&RIGHT(c_first_gy+15,2),IF(c_inst=2,(c_first_gy+INT(14/4))&" Q"&(MOD(14,4)+1),(c_first_gy+INT(14/12))&"-"&RIGHT("0"&(MOD(14,12)+1),2))))
A17: c_today_gy | B17: =IF(MONTH(TODAY())>=10,YEAR(TODAY()),YEAR(TODAY())-1) | D17: =IF(16>c_period_count,"",IF(c_inst=1,(c_first_gy+15)&"/"&RIGHT(c_first_gy+16,2),IF(c_inst=2,(c_first_gy+INT(15/4))&" Q"&(MOD(15,4)+1),(c_first_gy+INT(15/12))&"-"&RIGHT("0"&(MOD(15,12)+1),2))))
A18: c_last_gy | B18: =c_today_gy+2 | D18: =IF(17>c_period_count,"",IF(c_inst=1,(c_first_gy+16)&"/"&RIGHT(c_first_gy+17,2),IF(c_inst=2,(c_first_gy+INT(16/4))&" Q"&(MOD(16,4)+1),(c_first_gy+INT(16/12))&"-"&RIGHT("0"&(MOD(16,12)+1),2))))
A19: c_first_gy | B19: =IF(c_point_ok,MIN(c_last_gy,MAX(INDEX(pt_first_gy,c_id1),IF(c_bundle,INDEX(pt_first_gy,c_id2),0))),c_today_gy) | D19: =IF(18>c_period_count,"",IF(c_inst=1,(c_first_gy+17)&"/"&RIGHT(c_first_gy+18,2),IF(c_inst=2,(c_first_gy+INT(17/4))&" Q"&(MOD(17,4)+1),(c_first_gy+INT(17/12))&"-"&RIGHT("0"&(MOD(17,12)+1),2))))
A20: c_n_gy | B20: =c_last_gy-c_first_gy+1 | D20: =IF(19>c_period_count,"",IF(c_inst=1,(c_first_gy+18)&"/"&RIGHT(c_first_gy+19,2),IF(c_inst=2,(c_first_gy+INT(18/4))&" Q"&(MOD(18,4)+1),(c_first_gy+INT(18/12))&"-"&RIGHT("0"&(MOD(18,12)+1),2))))
A21: c_period_count | B21: =IF(c_inst=1,c_n_gy,IF(c_inst=2,4*(c_n_gy+1),IF(c_inst=3,12*(c_n_gy+1),0))) | D21: =IF(20>c_period_count,"",IF(c_inst=1,(c_first_gy+19)&"/"&RIGHT(c_first_gy+20,2),IF(c_inst=2,(c_first_gy+INT(19/4))&" Q"&(MOD(19,4)+1),(c_first_gy+INT(19/12))&"-"&RIGHT("0"&(MOD(19,12)+1),2))))
A22: c_period_pos | B22: =IF(AND(c_inst>=1,c_inst<=3,c_period_count>0),IFERROR(MATCH(in_period&"",dv_periods,0),0),0) | D22: =IF(21>c_period_count,"",IF(c_inst=1,(c_first_gy+20)&"/"&RIGHT(c_first_gy+21,2),IF(c_inst=2,(c_first_gy+INT(20/4))&" Q"&(MOD(20,4)+1),(c_first_gy+INT(20/12))&"-"&RIGHT("0"&(MOD(20,12)+1),2))))
A23: c_day_ok | B23: =AND(c_inst=4,ISNUMBER(in_day)) | D23: =IF(22>c_period_count,"",IF(c_inst=1,(c_first_gy+21)&"/"&RIGHT(c_first_gy+22,2),IF(c_inst=2,(c_first_gy+INT(21/4))&" Q"&(MOD(21,4)+1),(c_first_gy+INT(21/12))&"-"&RIGHT("0"&(MOD(21,12)+1),2))))
A24: c_period_ok | B24: =IF(c_inst=4,c_day_ok,c_period_pos>0) | D24: =IF(23>c_period_count,"",IF(c_inst=1,(c_first_gy+22)&"/"&RIGHT(c_first_gy+23,2),IF(c_inst=2,(c_first_gy+INT(22/4))&" Q"&(MOD(22,4)+1),(c_first_gy+INT(22/12))&"-"&RIGHT("0"&(MOD(22,12)+1),2))))
A25: c_py | B25: =c_first_gy+IF(c_inst=2,INT((c_period_pos-1)/4),IF(c_inst=3,INT((c_period_pos-1)/12),c_period_pos-1)) | D25: =IF(24>c_period_count,"",IF(c_inst=1,(c_first_gy+23)&"/"&RIGHT(c_first_gy+24,2),IF(c_inst=2,(c_first_gy+INT(23/4))&" Q"&(MOD(23,4)+1),(c_first_gy+INT(23/12))&"-"&RIGHT("0"&(MOD(23,12)+1),2))))
A26: c_pq | B26: =MOD(c_period_pos-1,4)+1 | D26: =IF(25>c_period_count,"",IF(c_inst=1,(c_first_gy+24)&"/"&RIGHT(c_first_gy+25,2),IF(c_inst=2,(c_first_gy+INT(24/4))&" Q"&(MOD(24,4)+1),(c_first_gy+INT(24/12))&"-"&RIGHT("0"&(MOD(24,12)+1),2))))
A27: c_pm | B27: =MOD(c_period_pos-1,12)+1 | D27: =IF(26>c_period_count,"",IF(c_inst=1,(c_first_gy+25)&"/"&RIGHT(c_first_gy+26,2),IF(c_inst=2,(c_first_gy+INT(25/4))&" Q"&(MOD(25,4)+1),(c_first_gy+INT(25/12))&"-"&RIGHT("0"&(MOD(25,12)+1),2))))
A28: c_start | B28: =IF(NOT(c_period_ok),"",CHOOSE(c_inst,DATE(c_py,10,1),DATE(c_py,3*c_pq-2,1),DATE(c_py,c_pm,1),INT(in_day))) | D28: =IF(27>c_period_count,"",IF(c_inst=1,(c_first_gy+26)&"/"&RIGHT(c_first_gy+27,2),IF(c_inst=2,(c_first_gy+INT(26/4))&" Q"&(MOD(26,4)+1),(c_first_gy+INT(26/12))&"-"&RIGHT("0"&(MOD(26,12)+1),2))))
A29: c_end | B29: =IF(NOT(c_period_ok),"",CHOOSE(c_inst,DATE(c_py+1,9,30),DATE(c_py,3*c_pq+1,0),DATE(c_py,c_pm+1,0),INT(in_day))) | D29: =IF(28>c_period_count,"",IF(c_inst=1,(c_first_gy+27)&"/"&RIGHT(c_first_gy+28,2),IF(c_inst=2,(c_first_gy+INT(27/4))&" Q"&(MOD(27,4)+1),(c_first_gy+INT(27/12))&"-"&RIGHT("0"&(MOD(27,12)+1),2))))
A30: c_unit_hours | B30: =IF(in_unit="kWh/h",24,IF(in_unit="kWh/d",1,0)) | D30: =IF(29>c_period_count,"",IF(c_inst=1,(c_first_gy+28)&"/"&RIGHT(c_first_gy+29,2),IF(c_inst=2,(c_first_gy+INT(28/4))&" Q"&(MOD(28,4)+1),(c_first_gy+INT(28/12))&"-"&RIGHT("0"&(MOD(28,12)+1),2))))
A31: c_capacity_ok | B31: =AND(ISNUMBER(in_capacity),IF(ISNUMBER(in_capacity),in_capacity>0,FALSE)) | D31: =IF(30>c_period_count,"",IF(c_inst=1,(c_first_gy+29)&"/"&RIGHT(c_first_gy+30,2),IF(c_inst=2,(c_first_gy+INT(29/4))&" Q"&(MOD(29,4)+1),(c_first_gy+INT(29/12))&"-"&RIGHT("0"&(MOD(29,12)+1),2))))
A32: c_kwh_d | B32: =IF(c_capacity_ok,in_capacity*c_unit_hours,0) | D32: =IF(31>c_period_count,"",IF(c_inst=1,(c_first_gy+30)&"/"&RIGHT(c_first_gy+31,2),IF(c_inst=2,(c_first_gy+INT(30/4))&" Q"&(MOD(30,4)+1),(c_first_gy+INT(30/12))&"-"&RIGHT("0"&(MOD(30,12)+1),2))))
A33: c_input_msg | B33: =IF(NOT(c_booking_ok),"Choose a booking type from the list.",IF(NOT(c_tso_ok),"Choose a TSO from the list.",IF(NOT(c_point_ok),"Choose a point from the list.",IF(c_inst=0,"Choose a product instrument from the list.",IF(NOT(c_period_ok),IF(c_inst=4,"Choose a product period.","Choose a period from the list."),IF(c_unit_hours=0,"Choose a unit from the list.",IF(NOT(c_capacity_ok),"Capacity must be a positive number.",""))))))) | D33: =IF(32>c_period_count,"",IF(c_inst=1,(c_first_gy+31)&"/"&RIGHT(c_first_gy+32,2),IF(c_inst=2,(c_first_gy+INT(31/4))&" Q"&(MOD(31,4)+1),(c_first_gy+INT(31/12))&"-"&RIGHT("0"&(MOD(31,12)+1),2))))
A34: c_inputs_ok | B34: =c_input_msg="" | D34: =IF(33>c_period_count,"",IF(c_inst=1,(c_first_gy+32)&"/"&RIGHT(c_first_gy+33,2),IF(c_inst=2,(c_first_gy+INT(32/4))&" Q"&(MOD(32,4)+1),(c_first_gy+INT(32/12))&"-"&RIGHT("0"&(MOD(32,12)+1),2))))
A35: c_notariff_msg | B35: =IF(sa_notariff,sa_missing_msg,IF(sb_notariff,sb_missing_msg,"")) | D35: =IF(34>c_period_count,"",IF(c_inst=1,(c_first_gy+33)&"/"&RIGHT(c_first_gy+34,2),IF(c_inst=2,(c_first_gy+INT(33/4))&" Q"&(MOD(33,4)+1),(c_first_gy+INT(33/12))&"-"&RIGHT("0"&(MOD(33,12)+1),2))))
A36: c_msg | B36: =IF(c_input_msg<>"",c_input_msg,c_notariff_msg) | D36: =IF(35>c_period_count,"",IF(c_inst=1,(c_first_gy+34)&"/"&RIGHT(c_first_gy+35,2),IF(c_inst=2,(c_first_gy+INT(34/4))&" Q"&(MOD(34,4)+1),(c_first_gy+INT(34/12))&"-"&RIGHT("0"&(MOD(34,12)+1),2))))
A37: c_ok | B37: =c_msg="" | D37: =IF(36>c_period_count,"",IF(c_inst=1,(c_first_gy+35)&"/"&RIGHT(c_first_gy+36,2),IF(c_inst=2,(c_first_gy+INT(35/4))&" Q"&(MOD(35,4)+1),(c_first_gy+INT(35/12))&"-"&RIGHT("0"&(MOD(35,12)+1),2))))
A38: c_heading | B38: =IF(c_ok,c_heading_label&": "&LOWER(in_instrument)&" "&YEAR(c_start)&"-"&RIGHT("0"&MONTH(c_start),2)&"-"&RIGHT("0"&DAY(c_start),2)&IF(c_start=c_end,""," to "&YEAR(c_end)&"-"&RIGHT("0"&MONTH(c_end),2)&"-"&RIGHT("0"&DAY(c_end),2)),"") | D38: =IF(37>c_period_count,"",IF(c_inst=1,(c_first_gy+36)&"/"&RIGHT(c_first_gy+37,2),IF(c_inst=2,(c_first_gy+INT(36/4))&" Q"&(MOD(36,4)+1),(c_first_gy+INT(36/12))&"-"&RIGHT("0"&(MOD(36,12)+1),2))))
A39: c_eur_on | B39: =AND(c_ok,c_bundle) | D39: =IF(38>c_period_count,"",IF(c_inst=1,(c_first_gy+37)&"/"&RIGHT(c_first_gy+38,2),IF(c_inst=2,(c_first_gy+INT(37/4))&" Q"&(MOD(37,4)+1),(c_first_gy+INT(37/12))&"-"&RIGHT("0"&(MOD(37,12)+1),2))))
A40: c_r1_cur | B40: =IF(AND(c_eur_on,sa_currency<>"EUR"),sa_currency,"") | D40: =IF(39>c_period_count,"",IF(c_inst=1,(c_first_gy+38)&"/"&RIGHT(c_first_gy+39,2),IF(c_inst=2,(c_first_gy+INT(38/4))&" Q"&(MOD(38,4)+1),(c_first_gy+INT(38/12))&"-"&RIGHT("0"&(MOD(38,12)+1),2))))
...

Sheet Lists
A1: Booking type | B1: Instrument | C1: Unit | E1: TSO | F1: TSO code | G1: Singles start | H1: Singles count | J1: Point label | K1: Side 1 id | L1: Side 2 id | M1: Heading | O1: Rate currency
A2: Bundled | B2: Gas year | C2: kWh/h | E2: Amber Grid | F2: AMBERGR | G2: 59 | H2: 1 | J2: Balassagyarmat HU>SK (FGSZ + Eustream) | K2: 38 | L2: 21 | M2: Balassagyarmat HU>SK (FGSZ + Eustream) | O2: CZK
A3: Single side | B3: Quarter | C3: kWh/d | E3: Bulgartransgaz | F3: BGTRGAZ | G3: 60 | H3: 13 | J3: Balassagyarmat SK>HU (Eustream + FGSZ) | K3: 26 | L3: 31 | M3: Balassagyarmat SK>HU (Eustream + FGSZ) | O3: HUF
A4: LNG entry | B4: Month | E4: DESFA | F4: DESFA | G4: 73 | H4: 6 | J4: Baumgarten AT>SK (Gas Connect Austria + Eustream) | K4: 49 | L4: 22 | M4: Baumgarten AT>SK (Gas Connect Austria + Eustream) | O4: PLN
B5: Day | E5: Eustream | F5: EUSTR | G5: 79 | H5: 10 | J5: Baumgarten SK>AT (Eustream + Gas Connect Austria) | K5: 27 | L5: 45 | M5: Baumgarten SK>AT (Eustream + Gas Connect Austria) | O5: RON
E6: FGSZ | F6: FGSZ | G6: 89 | H6: 14 | J6: Cieszyn CZ>PL (NET4GAS + GAZ-SYSTEM) | K6: 78 | L6: 67 | M6: Cieszyn CZ>PL (NET4GAS + GAZ-SYSTEM)
E7: Gas Connect Austria | F7: GCA | G7: 103 | H7: 8 | J7: Cieszyn PL>CZ (GAZ-SYSTEM + NET4GAS) | K7: 70 | L7: 75 | M7: Cieszyn PL>CZ (GAZ-SYSTEM + NET4GAS)
E8: Gas TSO of Ukraine | F8: UKRTRAG | G8: 111 | H8: 4 | J8: Csanádpalota HU>RO (FGSZ + Transgaz) | K8: 39 | L8: 104 | M8: Csanádpalota HU>RO (FGSZ + Transgaz)
E9: GASCADE | F9: GASCADE | G9: 115 | H9: 2 | J9: Csanádpalota RO>HU (Transgaz + FGSZ) | K9: 107 | L9: 33 | M9: Csanádpalota RO>HU (Transgaz + FGSZ)
E10: Gastrans | F10: Gastran | G10: 117 | H10: 4 | J10: Drávaszerdahely CR>HU (Plinacro + FGSZ) | K10: 85 | L10: 34 | M10: Drávaszerdahely CR>HU (Plinacro + FGSZ)
E11: Gasunie Deutschland | F11: Gasunie | G11: 121 | H11: 2 | J11: Drávaszerdahely HU>CR (FGSZ + Plinacro) | K11: 40 | L11: 83 | M11: Drávaszerdahely HU>CR (FGSZ + Plinacro)
E12: Gasunie Transport Services | F12: GTS | G12: 123 | H12: 2 | J12: Gorizia/Šempeter IT>SI (Snam Rete Gas + Plinovodi) | K12: 96 | L12: 87 | M12: Gorizia/Šempeter IT>SI (Snam Rete Gas + Plinovodi)
E13: GAZ-SYSTEM | F13: GAZSYS | G13: 125 | H13: 6 | J13: Gorizia/Šempeter SI>IT (Plinovodi + Snam Rete Gas) | K13: 90 | L13: 93 | M13: Gorizia/Šempeter SI>IT (Plinovodi + Snam Rete Gas)
E14: ICGB | F14: ICGB | G14: 131 | H14: 2 | J14: Kireevo/Zaychar BG>RS (Bulgartransgaz + Gastrans) | K14: 9 | L14: 59 | M14: Kireevo/Zaychar BG>RS (Bulgartransgaz + Gastrans)
E15: NET4GAS | F15: NET4GAS | G15: 133 | H15: 6 | J15: Kiskundorozsma 2 RS>HU (Gastrans + FGSZ) | K15: 62 | L15: 35 | M15: Kiskundorozsma 2 RS>HU (Gastrans + FGSZ)
E16: Open Grid Europe | F16: OGE | G16: 139 | H16: 2 | J16: Komotini TAP>ICGB (Trans Adriatic Pipeline + ICGB) | K16: 99 | L16: 73 | M16: Komotini TAP>ICGB (Trans Adriatic Pipeline + ICGB)
E17: Plinacro | F17: plinacr | G17: 141 | H17: 4 | J17: Kulata/Sidirokastron BG>GR (Bulgartransgaz + DESFA) | K17: 10 | L17: 16 | M17: Kulata/Sidirokastron BG>GR (Bulgartransgaz + DESFA)
... E22: Transgaz | F22: TRANSGA | G22: 162 | H22: 6 | J22: Murfeld/Ceršak AT>SI (Gas Connect Austria + Plinovodi) | K22: 51 | L22: 88 | M22: Murfeld/Ceršak AT>SI (Gas Connect Austria + Plinovodi)
J23: Nea Mesimvria TAP>GR (Trans Adriatic Pipeline + DESFA) | K23: 101 | L23: 17 | M23: Nea Mesimvria TAP>GR (Trans Adriatic Pipeline + DESFA)
J24: Negru Voda 1/Kardam BG>RO (Bulgartransgaz + Transgaz) | K24: 12 | L24: 105 | M24: Negru Voda 1/Kardam BG>RO (Bulgartransgaz + Transgaz)
J25: Negru Voda 1/Kardam RO>BG (Transgaz + Bulgartransgaz) | K25: 108 | L25: 4 | M25: Negru Voda 1/Kardam RO>BG (Transgaz + Bulgartransgaz)
J26: Rogatec CR>SI (Plinacro + Plinovodi) | K26: 86 | L26: 89 | M26: Rogatec CR>SI (Plinacro + Plinovodi)
J27: Rogatec SI>CR (Plinovodi + Plinacro) | K27: 92 | L27: 84 | M27: Rogatec SI>CR (Plinovodi + Plinacro)
J28: Ruse/Giurgiu BG>RO (Bulgartransgaz + Transgaz) | K28: 13 | L28: 106 | M28: Ruse/Giurgiu BG>RO (Bulgartransgaz + Transgaz)
J29: Ruse/Giurgiu RO>BG (Transgaz + Bulgartransgaz) | K29: 109 | L29: 5 | M29: Ruse/Giurgiu RO>BG (Transgaz + Bulgartransgaz)
J30: Stara Zagora ICGB>BG (ICGB + Bulgartransgaz) | K30: 74 | L30: 6 | M30: Stara Zagora ICGB>BG (ICGB + Bulgartransgaz)
J31: Tarvisio/Arnoldstein AT>IT (Trans Austria Gasleitung + Snam Rete Gas) | K31: 103 | L31: 95 | M31: Tarvisio/Arnoldstein AT>IT (Trans Austria Gasleitung + Snam Rete Gas)
J32: Tarvisio/Arnoldstein IT>AT (Snam Rete Gas + Trans Austria Gasleitung) | K32: 97 | L32: 102 | M32: Tarvisio/Arnoldstein IT>AT (Snam Rete Gas + Trans Austria Gasleitung)
J33: Uzhgorod/Velké Kapušany SK>UA (Eustream + Gas TSO of Ukraine) | K33: 29 | L33: 53 | M33: Uzhgorod/Velké Kapušany SK>UA (Eustream + Gas TSO of Ukraine)
J34: Uzhgorod/Velké Kapušany UA>SK (Gas TSO of Ukraine + Eustream) | K34: 55 | L34: 24 | M34: Uzhgorod/Velké Kapušany UA>SK (Gas TSO of Ukraine + Eustream)
... J44: Vyrava SK>PL (Eustream + GAZ-SYSTEM) | K44: 30 | L44: 69 | M44: Vyrava SK>PL (Eustream + GAZ-SYSTEM)
J45: Agia Triada (DESFA) | K45: 110 | M45: Agia Triada (DESFA)
J46: Amfitriti (DESFA) | K46: 111 | M46: Amfitriti (DESFA)
J47: Brunsbüttel Hafen (Gasunie Deutschland) | K47: 112 | M47: Brunsbüttel Hafen (Gasunie Deutschland)
J48: Cavarzere (Snam Rete Gas) | K48: 113 | M48: Cavarzere (Snam Rete Gas)
J49: Eems Energy Terminal (Gasunie Transport Services) | K49: 114 | M49: Eems Energy Terminal (Gasunie Transport Services)
J50: Gate Terminal (Gasunie Transport Services) | K50: 115 | M50: Gate Terminal (Gasunie Transport Services)
J51: Klaipeda (Amber Grid) | K51: 116 | M51: Klaipeda (Amber Grid)
J52: Omišalj (Plinacro) | K52: 117 | M52: Omišalj (Plinacro)
J53: Panigaglia (Snam Rete Gas) | K53: 118 | M53: Panigaglia (Snam Rete Gas)
...

Sheet Points
A1: Id | B1: TSO code | C1: TSO | D1: Direction | E1: EIC | F1: Name | G1: Capacity type | H1: Currency | I1: Unit | J1: First Tariffs row | K1: Stretches | L1: Earliest gas year
A2: 1 | B2: AMBERGR | C2: Amber Grid | D2: Exit | E2: 21Z180960164W65R | F2: Santaka (LT>PL) | G2: Firm | H2: EUR | I2: kWh/h | J2: 2 | K2: 3 | L2: 2024
A3: 2 | B3: BGTRGAZ | C3: Bulgartransgaz | D3: Entry | E3: 58Z-000000007-KZ | F3: Kireevo/Zaychar (RS>BG) | G3: Firm | H3: EUR | I3: kWh/d | J3: 5 | K3: 2 | L3: 2025
A4: 3 | B4: BGTRGAZ | C4: Bulgartransgaz | D4: Entry | E4: 21Z000000000020C | F4: Kulata/Sidirokastron (GR>BG) | G4: Firm | H4: EUR | I4: kWh/d | J4: 7 | K4: 2 | L4: 2025
A5: 4 | B5: BGTRGAZ | C5: Bulgartransgaz | D5: Entry | E5: 21Z000000000159I | F5: Negru Voda 1/Kardam (RO>BG) | G5: Firm | H5: EUR | I5: kWh/d | J5: 9 | K5: 2 | L5: 2025
A6: 5 | B6: BGTRGAZ | C6: Bulgartransgaz | D6: Entry | E6: 21Z0000000002798 | F6: Ruse/Giurgiu (RO>BG) | G6: Firm | H6: EUR | I6: kWh/d | J6: 11 | K6: 2 | L6: 2025
A7: 6 | B7: BGTRGAZ | C7: Bulgartransgaz | D7: Entry | E7: 58Z-IP-00034-STZ | F7: Stara Zagora (ICGB>BG) | G7: Firm | H7: EUR | I7: kWh/d | J7: 13 | K7: 2 | L7: 2025
A8: 7 | B8: BGTRGAZ | C8: Bulgartransgaz | D8: Entry | E8: 21Z000000000157M | F8: Strandzha 1/Malkoclar (TR>BG) | G8: Firm | H8: EUR | I8: kWh/d | J8: 15 | K8: 2 | L8: 2025
A9: 8 | B9: BGTRGAZ | C9: Bulgartransgaz | D9: Entry | E9: 58Z-00000015-S2M | F9: Strandzha 2/Malkoclar (TR>BG) | G9: Firm | H9: EUR | I9: kWh/d | J9: 17 | K9: 2 | L9: 2025
A10: 9 | B10: BGTRGAZ | C10: Bulgartransgaz | D10: Exit | E10: 58Z-000000007-KZ | F10: Kireevo/Zaychar (BG>RS) | G10: Firm | H10: EUR | I10: kWh/d | J10: 19 | K10: 2 | L10: 2025
A11: 10 | B11: BGTRGAZ | C11: Bulgartransgaz | D11: Exit | E11: 21Z000000000020C | F11: Kulata/Sidirokastron (BG>GR) | G11: Firm | H11: EUR | I11: kWh/d | J11: 21 | K11: 2 | L11: 2025
A12: 11 | B12: BGTRGAZ | C12: Bulgartransgaz | D12: Exit | E12: 21Z000000000137S | F12: Kyustendil/Zidilovo (BG>MK) | G12: Firm | H12: EUR | I12: kWh/d | J12: 23 | K12: 2 | L12: 2025
A13: 12 | B13: BGTRGAZ | C13: Bulgartransgaz | D13: Exit | E13: 21Z000000000159I | F13: Negru Voda 1/Kardam (BG>RO) | G13: Firm | H13: EUR | I13: kWh/d | J13: 25 | K13: 2 | L13: 2025
... A124: 123 | B124: GAZSYS | C124: GAZ-SYSTEM | D124: Entry | E124: 21Z000000000454G | F124: Świnoujście (LNG>PL) | G124: Firm | H124: PLN | I124: kWh/h | J124: 497 | K124: 2 | L124: 2025

Sheet Tariffs
A1: Point id | B1: First day | C1: Last day | D1: Valid from | E1: Open-ended | F1: Valid to | G1: Year | H1: Q1_Jan | I1: Q2_Apr | J1: Q3_Jul | K1: Q4_Oct | L1: M_Jan | M1: M_Feb | N1: M_Mar | O1: M_Apr | P1: M_Maj | Q1: M_Jun | R1: M_Jul | S1: M_Aug | T1: M_Sep | U1: M_Oct | V1: M_Nov | W1: M_Dec | X1: D_Jan | Y1: D_Feb | Z1: D_Mar | AA1: D_Apr | AB1: D_Maj | AC1: D_Jun | AD1: D_Jul | AE1: D_Aug | AF1: D_Sep | AG1: D_Oct | AH1: D_Nov | AI1: D_Dec
A2: 1 | B2: 45658 | C2: 46022 | D2: 45658 | E2: 0 | F2: 46022 | G2: 2.0236 | H2: 0.5486 | I2: 0.5547 | J2: 0.5608 | K2: 0.5608 | L2: 0.215 | M2: 0.1942 | N2: 0.215 | O2: 0.2081 | P2: 0.215 | Q2: 0.2081 | R2: 0.215 | S2: 0.215 | T2: 0.2081 | U2: 0.215 | V2: 0.2081 | W2: 0.215 | X2: 0.0083 | Y2: 0.0083 | Z2: 0.0083 | AA2: 0.0083 | AB2: 0.0083 | AC2: 0.0083 | AD2: 0.0083 | AE2: 0.0083 | AF2: 0.0083 | AG2: 0.0083 | AH2: 0.0083 | AI2: 0.0083
A3: 1 | B3: 46023 | C3: 46387 | D3: 46023 | E3: 0 | F3: 46387 | G3: 4.08216 | H3: 1.10808 | I3: 1.120392 | J3: 1.132704 | K3: 1.132704 | L3: 0.433752 | M3: 0.391776 | N3: 0.433752 | O3: 0.41976 | P3: 0.433752 | Q3: 0.41976 | R3: 0.433752 | S3: 0.433752 | T3: 0.41976 | U3: 0.433752 | V3: 0.41976 | W3: 0.433752 | X3: 0.0168 | Y3: 0.0168 | Z3: 0.0168 | AA3: 0.0168 | AB3: 0.0168 | AC3: 0.0168 | AD3: 0.0168 | AE3: 0.0168 | AF3: 0.0168 | AG3: 0.0168 | AH3: 0.0168 | AI3: 0.0168
A4: 1 | B4: 46388 | C4: 2958465 | D4: 46388 | E4: 1 | G4: 3.35508 | H4: 0.90936 | I4: 0.919464 | J4: 0.929568 | K4: 0.929568 | L4: 0.355632 | M4: 0.321216 | N4: 0.355632 | O4: 0.34416 | P4: 0.355632 | Q4: 0.34416 | R4: 0.355632 | S4: 0.355632 | T4: 0.34416 | U4: 0.355632 | V4: 0.34416 | W4: 0.355632 | X4: 0.01368 | Y4: 0.01368 | Z4: 0.01368 | AA4: 0.01368 | AB4: 0.01368 | AC4: 0.01368 | AD4: 0.01368 | AE4: 0.01368 | AF4: 0.01368 | AG4: 0.01368 | AH4: 0.01368 | AI4: 0.01368
A5: 2 | B5: 46023 | C5: 46295 | D5: 46023 | E5: 0 | F5: 46295 | G5: 0.1622518 | H5: 0.0696927 | I5: 0.0462769 | J5: 0.0361524 | K5: 0.0590134 | L5: 0.027781 | M5: 0.0242213 | N5: 0.0227651 | O5: 0.0214706 | P5: 0.0163986 | Q5: 0.0117622 | R5: 0.0119613 | S5: 0.0113825 | T5: 0.0153095 | U5: 0.0183278 | V5: 0.0209105 | W5: 0.0243085 | X5: 0.0012802 | Y5: 0.0012358 | Z5: 0.0010491 | AA5: 0.0010224 | AB5: 0.0007557 | AC5: 0.0005601 | AD5: 0.0005512 | AE5: 0.0005245 | AF5: 0.000729 | AG5: 0.0008446 | AH5: 0.0009957 | AI5: 0.0011202
A6: 2 | B6: 46296 | C6: 2958465 | D6: 46296 | E6: 1 | G6: 0.1627475 | H6: 0.0704273 | I6: 0.0458908 | J6: 0.0351963 | K6: 0.0602603 | L6: 0.0278659 | M6: 0.0251692 | N6: 0.0226411 | O6: 0.0219107 | P6: 0.0160616 | Q6: 0.0112363 | R6: 0.0119978 | S6: 0.0106432 | T6: 0.015169 | U6: 0.0189643 | V6: 0.0213489 | W6: 0.0243827 | X6: 0.0012841 | Y6: 0.0012841 | Z6: 0.0010434 | AA6: 0.0010434 | AB6: 0.0007402 | AC6: 0.0005351 | AD6: 0.0005529 | AE6: 0.0004905 | AF6: 0.0007223 | AG6: 0.0008739 | AH6: 0.0010166 | AI6: 0.0011236
A7: 3 | B7: 46023 | C7: 46295 | D7: 46023 | E7: 0 | F7: 46295 | G7: 0.1327455 | H7: 0.0570187 | I7: 0.0378612 | J7: 0.0295779 | K7: 0.0482815 | L7: 0.0227289 | M7: 0.0198165 | N7: 0.0186251 | O7: 0.017566 | P7: 0.0134164 | Q7: 0.0096231 | R7: 0.0097861 | S7: 0.0093126 | T7: 0.0125254 | U7: 0.0149948 | V7: 0.0171078 | W7: 0.0198878 | X7: 0.0010474 | Y7: 0.001011 | Z7: 0.0008583 | AA7: 0.0008365 | AB7: 0.0006183 | AC7: 0.0004582 | AD7: 0.000451 | AE7: 0.0004291 | AF7: 0.0005964 | AG7: 0.000691 | AH7: 0.0008146 | AI7: 0.0009165
A8: 3 | B8: 46296 | C8: 2958465 | D8: 46296 | E8: 1 | G8: 0.1228801 | H8: 0.0531751 | I8: 0.0346492 | J8: 0.0265744 | K8: 0.0454986 | L8: 0.0210398 | M8: 0.0190037 | N8: 0.0170948 | O8: 0.0165434 | P8: 0.0121271 | Q8: 0.0084838 | R8: 0.0090588 | S8: 0.008036 | T8: 0.0114531 | U8: 0.0143187 | V8: 0.0161192 | W8: 0.0184098 | X8: 0.0009696 | Y8: 0.0009696 | Z8: 0.0007878 | AA8: 0.0007878 | AB8: 0.0005589 | AC8: 0.000404 | AD8: 0.0004175 | AE8: 0.0003703 | AF8: 0.0005454 | AG8: 0.0006598 | AH8: 0.0007676 | AI8: 0.0008484
A9: 4 | B9: 46023 | C9: 46295 | D9: 46023 | E9: 0 | F9: 46295 | G9: 0.162534 | H9: 0.0698139 | I9: 0.0463574 | J9: 0.0362153 | K9: 0.059116 | L9: 0.0278294 | M9: 0.0242634 | N9: 0.0228046 | O9: 0.0215079 | P9: 0.016427 | Q9: 0.0117826 | R9: 0.0119821 | S9: 0.0114023 | T9: 0.0153361 | U9: 0.0183597 | V9: 0.0209469 | W9: 0.0243507 | X9: 0.0012825 | Y9: 0.0012379 | Z9: 0.0010509 | AA9: 0.0010242 | AB9: 0.000757 | AC9: 0.0005611 | AD9: 0.0005522 | AE9: 0.0005255 | AF9: 0.0007303 | AG9: 0.0008461 | AH9: 0.0009975 | AI9: 0.0011221
A10: 4 | B10: 46296 | C10: 2958465 | D10: 46296 | E10: 1 | G10: 0.1630046 | H10: 0.0705386 | I10: 0.0459633 | J10: 0.0352519 | K10: 0.0603555 | L10: 0.02791 | M10: 0.025209 | N10: 0.0226768 | O10: 0.0219453 | P10: 0.016087 | Q10: 0.011254 | R10: 0.0120168 | S10: 0.0106601 | T10: 0.0151929 | U10: 0.0189943 | V10: 0.0213826 | W10: 0.0244212 | X10: 0.0012862 | Y10: 0.0012862 | Z10: 0.001045 | AA10: 0.001045 | AB10: 0.0007413 | AC10: 0.0005359 | AD10: 0.0005538 | AE10: 0.0004912 | AF10: 0.0007235 | AG10: 0.0008753 | AH10: 0.0010182 | AI10: 0.0011254
A11: 5 | B11: 46023 | C11: 46295 | D11: 46023 | E11: 0 | F11: 46295 | G11: 0.1623144 | H11: 0.0697196 | I11: 0.0462947 | J11: 0.0361663 | K11: 0.0590362 | L11: 0.0277918 | M11: 0.0242306 | N11: 0.0227738 | O11: 0.0214789 | P11: 0.0164049 | Q11: 0.0117667 | R11: 0.0119659 | S11: 0.0113869 | T11: 0.0153153 | U11: 0.0183349 | V11: 0.0209185 | W11: 0.0243178 | X11: 0.0012807 | Y11: 0.0012363 | Z11: 0.0010495 | AA11: 0.0010228 | AB11: 0.000756 | AC11: 0.0005603 | AD11: 0.0005514 | AE11: 0.0005247 | AF11: 0.0007293 | AG11: 0.0008449 | AH11: 0.0009961 | AI11: 0.0011206
A12: 5 | B12: 46296 | C12: 2958465 | D12: 46296 | E12: 1 | G12: 0.1612439 | H12: 0.0697766 | I12: 0.0454668 | J12: 0.0348711 | K12: 0.0597035 | L12: 0.0276085 | M12: 0.0249367 | N12: 0.0224319 | O12: 0.0217083 | P12: 0.0159132 | Q12: 0.0113125 | R12: 0.011887 | S12: 0.0105449 | T12: 0.0150288 | U12: 0.0187891 | V12: 0.0211517 | W12: 0.0241574 | X12: 0.0012723 | Y12: 0.0012723 | Z12: 0.0010337 | AA12: 0.0010337 | AB12: 0.0007333 | AC12: 0.0005301 | AD12: 0.0005478 | AE12: 0.0004859 | AF12: 0.0007157 | AG12: 0.0008659 | AH12: 0.0010072 | AI12: 0.0011132
A13: 6 | B13: 46023 | C13: 46295 | D13: 46023 | E13: 0 | F13: 46295 | G13: 0.1233752 | H13: 0.0529939 | I13: 0.0351886 | J13: 0.02749 | K13: 0.0448734 | L13: 0.0211245 | M13: 0.0184177 | N13: 0.0173104 | O13: 0.0163261 | P13: 0.0124693 | Q13: 0.0089439 | R13: 0.0090953 | S13: 0.0086552 | T13: 0.0116412 | U13: 0.0139363 | V13: 0.0159002 | W13: 0.018484 | X13: 0.0009735 | Y13: 0.0009397 | Z13: 0.0007977 | AA13: 0.0007774 | AB13: 0.0005746 | AC13: 0.0004259 | AD13: 0.0004192 | AE13: 0.0003989 | AF13: 0.0005543 | AG13: 0.0006422 | AH13: 0.0007572 | AI13: 0.0008518
A14: 6 | B14: 46296 | C14: 2958465 | D14: 46296 | E14: 1 | G14: 0.1227019 | H14: 0.053098 | I14: 0.0345989 | J14: 0.0265359 | K14: 0.0454326 | L14: 0.0210093 | M14: 0.0189761 | N14: 0.01707 | O14: 0.0165194 | P14: 0.0121095 | Q14: 0.0084715 | R14: 0.0090457 | S14: 0.0080244 | T14: 0.0114365 | U14: 0.014298 | V14: 0.0160958 | W14: 0.0183831 | X14: 0.0009682 | Y14: 0.0009682 | Z14: 0.0007866 | AA14: 0.0007866 | AB14: 0.000558 | AC14: 0.0004034 | AD14: 0.0004169 | AE14: 0.0003698 | AF14: 0.0005446 | AG14: 0.0006589 | AH14: 0.0007665 | AI14: 0.0008471
A15: 7 | B15: 46023 | C15: 46295 | D15: 46023 | E15: 0 | F15: 46295 | G15: 0.2654889 | H15: 0.1140365 | I15: 0.0757218 | J15: 0.0591553 | K15: 0.0965623 | L15: 0.0454575 | M15: 0.0396327 | N15: 0.0372499 | O15: 0.0351318 | P15: 0.0268325 | Q15: 0.0192461 | R15: 0.019572 | S15: 0.0186249 | T15: 0.0250505 | U15: 0.0299893 | V15: 0.0342153 | W15: 0.0397753 | X15: 0.0020948 | Y15: 0.0020221 | Z15: 0.0017166 | AA15: 0.0016729 | AB15: 0.0012365 | AC15: 0.0009165 | AD15: 0.0009019 | AE15: 0.0008583 | AF15: 0.0011929 | AG15: 0.001382 | AH15: 0.0016293 | AI15: 0.001833
A16: 7 | B16: 46296 | C16: 2958465 | D16: 46296 | E16: 1 | G16: 0.2654036 | H16: 0.1148507 | I16: 0.0748373 | J16: 0.057397 | K16: 0.0982706 | L16: 0.0454429 | M16: 0.0410452 | N16: 0.0369224 | O16: 0.0357313 | P16: 0.0261928 | Q16: 0.0183238 | R16: 0.0195657 | S16: 0.0173567 | T16: 0.0247371 | U16: 0.0309264 | V16: 0.0348151 | W16: 0.0397625 | X16: 0.0020941 | Y16: 0.0020941 | Z16: 0.0017015 | AA16: 0.0017015 | AB16: 0.001207 | AC16: 0.0008726 | AD16: 0.0009016 | AE16: 0.0007998 | AF16: 0.001178 | AG16: 0.0014252 | AH16: 0.0016579 | AI16: 0.0018324
A17: 8 | B17: 46023 | C17: 46295 | D17: 46023 | E17: 0 | F17: 46295 | G17: 0.2654889 | H17: 0.1140365 | I17: 0.0757218 | J17: 0.0591553 | K17: 0.0965623 | L17: 0.0454575 | M17: 0.0396327 | N17: 0.0372499 | O17: 0.0351318 | P17: 0.0268325 | Q17: 0.0192461 | R17: 0.019572 | S17: 0.0186249 | T17: 0.0250505 | U17: 0.0299893 | V17: 0.0342153 | W17: 0.0397753 | X17: 0.0020948 | Y17: 0.0020221 | Z17: 0.0017166 | AA17: 0.0016729 | AB17: 0.0012365 | AC17: 0.0009165 | AD17: 0.0009019 | AE17: 0.0008583 | AF17: 0.0011929 | AG17: 0.001382 | AH17: 0.0016293 | AI17: 0.001833
A18: 8 | B18: 46296 | C18: 2958465 | D18: 46296 | E18: 1 | G18: 0.2654036 | H18: 0.1148507 | I18: 0.0748373 | J18: 0.057397 | K18: 0.0982706 | L18: 0.0454429 | M18: 0.0410452 | N18: 0.0369224 | O18: 0.0357313 | P18: 0.0261928 | Q18: 0.0183238 | R18: 0.0195657 | S18: 0.0173567 | T18: 0.0247371 | U18: 0.0309264 | V18: 0.0348151 | W18: 0.0397625 | X18: 0.0020941 | Y18: 0.0020941 | Z18: 0.0017015 | AA18: 0.0017015 | AB18: 0.001207 | AC18: 0.0008726 | AD18: 0.0009016 | AE18: 0.0007998 | AF18: 0.001178 | AG18: 0.0014252 | AH18: 0.0016579 | AI18: 0.0018324
A19: 9 | B19: 46023 | C19: 46295 | D19: 46023 | E19: 0 | F19: 46295 | G19: 0.3252076 | H19: 0.1396878 | I19: 0.0927545 | J19: 0.0724616 | K19: 0.1182829 | L19: 0.0556827 | M19: 0.0485477 | N19: 0.0456289 | O19: 0.0430343 | P19: 0.0328682 | Q19: 0.0235753 | R19: 0.0239745 | S19: 0.0228144 | T19: 0.0306853 | U19: 0.0367351 | V19: 0.0419117 | W19: 0.0487223 | X19: 0.002566 | Y19: 0.0024769 | Z19: 0.0021027 | AA19: 0.0020493 | AB19: 0.0015147 | AC19: 0.0011226 | AD19: 0.0011048 | AE19: 0.0010514 | AF19: 0.0014612 | AG19: 0.0016928 | AH19: 0.0019958 | AI19: 0.0022453
A20: 9 | B20: 46296 | C20: 2958465 | D20: 46296 | E20: 1 | G20: 0.3270835 | H20: 0.141542 | I20: 0.0922295 | J20: 0.0707361 | K20: 0.1211087 | L20: 0.0560039 | M20: 0.0505841 | N20: 0.0455031 | O20: 0.0440353 | P20: 0.03228 | Q20: 0.0225822 | R20: 0.0241128 | S20: 0.0213904 | T20: 0.030486 | U20: 0.0381137 | V20: 0.0429062 | W20: 0.0490034 | X20: 0.0025808 | Y20: 0.0025808 | Z20: 0.0020969 | AA20: 0.0020969 | AB20: 0.0014876 | AC20: 0.0010753 | AD20: 0.0011112 | AE20: 0.0009857 | AF20: 0.0014517 | AG20: 0.0017564 | AH20: 0.0020432 | AI20: 0.0022582
A21: 10 | B21: 46023 | C21: 46295 | D21: 46023 | E21: 0 | F21: 46295 | G21: 0.2150324 | H21: 0.0923638 | I21: 0.0613308 | J21: 0.0479128 | K21: 0.0782105 | L21: 0.0368183 | M21: 0.0321005 | N21: 0.0301705 | O21: 0.028455 | P21: 0.021733 | Q21: 0.0155884 | R21: 0.0158523 | S21: 0.0150853 | T21: 0.0202896 | U21: 0.0242898 | V21: 0.0277127 | W21: 0.032216 | X21: 0.0016967 | Y21: 0.0016378 | Z21: 0.0013904 | AA21: 0.001355 | AB21: 0.0010015 | AC21: 0.0007423 | AD21: 0.0007305 | AE21: 0.0006952 | AF21: 0.0009662 | AG21: 0.0011194 | AH21: 0.0013196 | AI21: 0.0014846
A22: 10 | B22: 46296 | C22: 2958465 | D22: 46296 | E22: 1 | G22: 0.2073493 | H22: 0.0897283 | I22: 0.0584674 | J22: 0.044842 | K22: 0.0767749 | L22: 0.0355027 | M22: 0.032067 | N22: 0.028846 | O22: 0.0279155 | P22: 0.0204634 | Q22: 0.0143156 | R22: 0.0152859 | S22: 0.0135601 | T22: 0.0193261 | U22: 0.0241616 | V22: 0.0271997 | W22: 0.0310649 | X22: 0.0016361 | Y22: 0.0016361 | Z22: 0.0013293 | AA22: 0.0013293 | AB22: 0.000943 | AC22: 0.0006817 | AD22: 0.0007044 | AE22: 0.0006249 | AF22: 0.0009203 | AG22: 0.0011134 | AH22: 0.0012952 | AI22: 0.0014316
A23: 11 | B23: 46023 | C23: 46295 | D23: 46023 | E23: 0 | F23: 46295 | G23: 0.1772807 | H23: 0.0761481 | I23: 0.0505634 | J23: 0.0395011 | K23: 0.0644797 | L23: 0.0303543 | M23: 0.0264649 | N23: 0.0248737 | O23: 0.0234593 | P23: 0.0179175 | Q23: 0.0128516 | R23: 0.0130692 | S23: 0.0124369 | T23: 0.0167275 | U23: 0.0200255 | V23: 0.0228474 | W23: 0.0265601 | X23: 0.0013988 | Y23: 0.0013503 | Z23: 0.0011463 | AA23: 0.0011171 | AB23: 0.0008257 | AC23: 0.000612 | AD23: 0.0006023 | AE23: 0.0005731 | AF23: 0.0007965 | AG23: 0.0009228 | AH23: 0.001088 | AI23: 0.001224
A24: 11 | B24: 46296 | C24: 2958465 | D24: 46296 | E24: 1 | G24: 0.1778454 | H24: 0.0769608 | I24: 0.050148 | J24: 0.0384614 | K24: 0.0658505 | L24: 0.030451 | M24: 0.0275042 | N24: 0.0247415 | O24: 0.0239434 | P24: 0.0175516 | Q24: 0.0122786 | R24: 0.0131109 | S24: 0.0116306 | T24: 0.0165762 | U24: 0.0207236 | V24: 0.0233294 | W24: 0.0266447 | X24: 0.0014033 | Y24: 0.0014033 | Z24: 0.0011402 | AA24: 0.0011402 | AB24: 0.0008088 | AC24: 0.0005847 | AD24: 0.0006042 | AE24: 0.000536 | AF24: 0.0007893 | AG24: 0.000955 | AH24: 0.0011109 | AI24: 0.0012279
A25: 12 | B25: 46023 | C25: 46295 | D25: 46023 | E25: 0 | F25: 46295 | G25: 0.1395938 | H25: 0.0599603 | I25: 0.0398145 | J25: 0.0311038 | K25: 0.0507724 | L25: 0.0239015 | M25: 0.0208389 | N25: 0.019586 | O25: 0.0184723 | P25: 0.0141085 | Q25: 0.0101196 | R25: 0.0102909 | S25: 0.009793 | T25: 0.0131715 | U25: 0.0157683 | V25: 0.0179904 | W25: 0.0209138 | X25: 0.0011015 | Y25: 0.0010632 | Z25: 0.0009026 | AA25: 0.0008796 | AB25: 0.0006502 | AC25: 0.0004819 | AD25: 0.0004742 | AE25: 0.0004513 | AF25: 0.0006272 | AG25: 0.0007266 | AH25: 0.0008567 | AI25: 0.0009638
A26: 12 | B26: 46296 | C26: 2958465 | D26: 46296 | E26: 1 | G26: 0.1326972 | H26: 0.0574233 | I26: 0.0374173 | J26: 0.0286975 | K26: 0.0491336 | L26: 0.0227207 | M26: 0.0205219 | N26: 0.0184065 | O26: 0.017865 | P26: 0.0130959 | Q26: 0.0091616 | R26: 0.0097825 | S26: 0.008678 | T26: 0.0123681 | U26: 0.0154627 | V26: 0.017407 | W26: 0.0198806 | X26: 0.001047 | Y26: 0.001047 | Z26: 0.0008507 | AA26: 0.0008507 | AB26: 0.0006035 | AC26: 0.0004363 | AD26: 0.0004508 | AE26: 0.0003999 | AF26: 0.000589 | AG26: 0.0007126 | AH26: 0.0008289 | AI26: 0.0009162
A27: 13 | B27: 46023 | C27: 46295 | D27: 46023 | E27: 0 | F27: 46295 | G27: 0.1647855 | H27: 0.070781 | I27: 0.0469995 | J27: 0.0367169 | K27: 0.059935 | L27: 0.0282149 | M27: 0.0245995 | N27: 0.0231205 | O27: 0.0218059 | P27: 0.0166546 | Q27: 0.0119458 | R27: 0.0121481 | S27: 0.0115603 | T27: 0.0155485 | U27: 0.018614 | V27: 0.021237 | W27: 0.024688 | X27: 0.0013002 | Y27: 0.0012551 | Z27: 0.0010655 | AA27: 0.0010384 | AB27: 0.0007675 | AC27: 0.0005689 | AD27: 0.0005598 | AE27: 0.0005327 | AF27: 0.0007404 | AG27: 0.0008578 | AH27: 0.0010113 | AI27: 0.0011377
A28: 13 | B28: 46296 | C28: 2958465 | D28: 46296 | E28: 1 | G28: 0.1663607 | H28: 0.0719909 | I28: 0.0469096 | J28: 0.0359777 | K28: 0.0615981 | L28: 0.0284846 | M28: 0.025728 | N28: 0.0231437 | O28: 0.0223972 | P28: 0.0164182 | Q28: 0.0114857 | R28: 0.0122642 | S28: 0.0108795 | T28: 0.0155057 | U28: 0.0193854 | V28: 0.0218229 | W28: 0.0242924 | X28: 0.0013127 | Y28: 0.0013127 | Z28: 0.0010665 | AA28: 0.0010665 | AB28: 0.0007566 | AC28: 0.0005469 | AD28: 0.0005652 | AE28: 0.0005014 | AF28: 0.0007384 | AG28: 0.0008933 | AH28: 0.0010392 | AI28: 0.0011486
A29: 14 | B29: 46023 | C29: 46295 | D29: 46023 | E29: 0 | F29: 46295 | G29: 0.1647738 | H29: 0.070776 | I29: 0.0469962 | J29: 0.0367143 | K29: 0.0599307 | L29: 0.0282129 | M29: 0.0245978 | N29: 0.0231189 | O29: 0.0218043 | P29: 0.0166534 | Q29: 0.011945 | R29: 0.0121472 | S29: 0.0115594 | T29: 0.0155474 | U29: 0.0186127 | V29: 0.0212355 | W29: 0.0246863 | X29: 0.0013001 | Y29: 0.001255 | Z29: 0.0010654 | AA29: 0.0010383 | AB29: 0.0007674 | AC29: 0.0005688 | AD29: 0.0005598 | AE29: 0.0005327 | AF29: 0.0007404 | AG29: 0.0008577 | AH29: 0.0010112 | AI29: 0.0011376
A30: 14 | B30: 46296 | C30: 2958465 | D30: 46296 | E30: 1 | G30: 0.1668688 | H30: 0.0722108 | I30: 0.0470529 | J30: 0.0360875 | K30: 0.0617863 | L30: 0.0285716 | M30: 0.0258066 | N30: 0.0232144 | O30: 0.0224656 | P30: 0.0164684 | Q30: 0.0115208 | R30: 0.0123017 | S30: 0.0109128 | T30: 0.0155531 | U30: 0.0194446 | V30: 0.0218895 | W30: 0.0250001 | X30: 0.0013167 | Y30: 0.0013167 | Z30: 0.0010698 | AA30: 0.0010698 | AB30: 0.0007589 | AC30: 0.0005486 | AD30: 0.0005669 | AE30: 0.0005029 | AF30: 0.0007406 | AG30: 0.0008961 | AH30: 0.0010424 | AI30: 0.0011521
A31: 15 | B31: 46023 | C31: 46387 | D31: 46023 | E31: 0 | F31: 46387 | G31: 3.5742399 | H31: 1.2157802 | I31: 1.2292888 | J31: 1.2427975 | K31: 1.2427975 | L31: 0.4492467 | M31: 0.40577122 | N31: 0.4492467 | O31: 0.43475487 | P31: 0.4492467 | Q31: 0.43475487 | R31: 0.4492467 | S31: 0.4492467 | T31: 0.43475487 | U31: 0.4492467 | V31: 0.43475487 | W31: 0.4492467 | X31: 0.02909725 | Y31: 0.02909725 | Z31: 0.02909725 | AA31: 0.02909725 | AB31: 0.02909725 | AC31: 0.02909725 | AD31: 0.02909725 | AE31: 0.02909725 | AF31: 0.02909725 | AG31: 0.02909725 | AH31: 0.02909725 | AI31: 0.02909725
A32: 15 | B32: 46388 | C32: 2958465 | D32: 46388 | E32: 1 | G32: 3.7509292 | H32: 1.2758811 | I32: 1.2900576 | J32: 1.3042341 | K32: 1.3042341 | L32: 0.4714548 | M32: 0.42583015 | N32: 0.4714548 | O32: 0.45624659 | P32: 0.4714548 | Q32: 0.45624659 | R32: 0.4714548 | S32: 0.4714548 | T32: 0.45624659 | U32: 0.4714548 | V32: 0.45624659 | W32: 0.4714548 | X32: 0.03053565 | Y32: 0.03053565 | Z32: 0.03053565 | AA32: 0.03053565 | AB32: 0.03053565 | AC32: 0.03053565 | AD32: 0.03053565 | AE32: 0.03053565 | AF32: 0.03053565 | AG32: 0.03053565 | AH32: 0.03053565 | AI32: 0.03053565
A33: 16 | B33: 46023 | C33: 46387 | D33: 46023 | E33: 0 | F33: 46387 | G33: 3.5742399 | H33: 1.2157802 | I33: 1.2292888 | J33: 1.2427975 | K33: 1.2427975 | L33: 0.4492467 | M33: 0.40577122 | N33: 0.4492467 | O33: 0.43475487 | P33: 0.4492467 | Q33: 0.43475487 | R33: 0.4492467 | S33: 0.4492467 | T33: 0.43475487 | U33: 0.4492467 | V33: 0.43475487 | W33: 0.4492467 | X33: 0.02909725 | Y33: 0.02909725 | Z33: 0.02909725 | AA33: 0.02909725 | AB33: 0.02909725 | AC33: 0.02909725 | AD33: 0.02909725 | AE33: 0.02909725 | AF33: 0.02909725 | AG33: 0.02909725 | AH33: 0.02909725 | AI33: 0.02909725
A34: 16 | B34: 46388 | C34: 2958465 | D34: 46388 | E34: 1 | G34: 3.7509292 | H34: 1.2758811 | I34: 1.2900576 | J34: 1.3042341 | K34: 1.3042341 | L34: 0.4714548 | M34: 0.42583015 | N34: 0.4714548 | O34: 0.45624659 | P34: 0.4714548 | Q34: 0.45624659 | R34: 0.4714548 | S34: 0.4714548 | T34: 0.45624659 | U34: 0.4714548 | V34: 0.45624659 | W34: 0.4714548 | X34: 0.03053565 | Y34: 0.03053565 | Z34: 0.03053565 | AA34: 0.03053565 | AB34: 0.03053565 | AC34: 0.03053565 | AD34: 0.03053565 | AE34: 0.03053565 | AF34: 0.03053565 | AG34: 0.03053565 | AH34: 0.03053565 | AI34: 0.03053565
A35: 17 | B35: 46023 | C35: 46387 | D35: 46023 | E35: 0 | F35: 46387 | G35: 3.5742399 | H35: 1.2157802 | I35: 1.2292888 | J35: 1.2427975 | K35: 1.2427975 | L35: 0.4492467 | M35: 0.40577122 | N35: 0.4492467 | O35: 0.43475487 | P35: 0.4492467 | Q35: 0.43475487 | R35: 0.4492467 | S35: 0.4492467 | T35: 0.43475487 | U35: 0.4492467 | V35: 0.43475487 | W35: 0.4492467 | X35: 0.02909725 | Y35: 0.02909725 | Z35: 0.02909725 | AA35: 0.02909725 | AB35: 0.02909725 | AC35: 0.02909725 | AD35: 0.02909725 | AE35: 0.02909725 | AF35: 0.02909725 | AG35: 0.02909725 | AH35: 0.02909725 | AI35: 0.02909725
A36: 17 | B36: 46388 | C36: 2958465 | D36: 46388 | E36: 1 | G36: 3.7509292 | H36: 1.2758811 | I36: 1.2900576 | J36: 1.3042341 | K36: 1.3042341 | L36: 0.4714548 | M36: 0.42583015 | N36: 0.4714548 | O36: 0.45624659 | P36: 0.4714548 | Q36: 0.45624659 | R36: 0.4714548 | S36: 0.4714548 | T36: 0.45624659 | U36: 0.4714548 | V36: 0.45624659 | W36: 0.4714548 | X36: 0.03053565 | Y36: 0.03053565 | Z36: 0.03053565 | AA36: 0.03053565 | AB36: 0.03053565 | AC36: 0.03053565 | AD36: 0.03053565 | AE36: 0.03053565 | AF36: 0.03053565 | AG36: 0.03053565 | AH36: 0.03053565 | AI36: 0.03053565
A37: 18 | B37: 46023 | C37: 46387 | D37: 46023 | E37: 0 | F37: 46387 | G37: 4.6287243 | H37: 1.5744637 | I37: 1.5919578 | J37: 1.6094518 | K37: 1.6094518 | L37: 0.58178499 | M37: 0.52548322 | N37: 0.58178499 | O37: 0.56301773 | P37: 0.58178499 | Q37: 0.56301773 | R37: 0.58178499 | S37: 0.58178499 | T37: 0.56301773 | U37: 0.58178499 | V37: 0.56301773 | W37: 0.58178499 | X37: 0.03768162 | Y37: 0.03768162 | Z37: 0.03768162 | AA37: 0.03768162 | AB37: 0.03768162 | AC37: 0.03768162 | AD37: 0.03768162 | AE37: 0.03768162 | AF37: 0.03768162 | AG37: 0.03768162 | AH37: 0.03768162 | AI37: 0.03768162
A38: 18 | B38: 46388 | C38: 2958465 | D38: 46388 | E38: 1 | G38: 3.9763315 | H38: 1.0785118 | I38: 1.0904953 | J38: 1.1024788 | K38: 1.1024788 | L38: 0.40525899 | M38: 0.36604038 | N38: 0.40525899 | O38: 0.39218612 | P38: 0.40525899 | Q38: 0.39218612 | R38: 0.40525899 | S38: 0.40525899 | T38: 0.39218612 | U38: 0.40525899 | V38: 0.39218612 | W38: 0.40525899 | X38: 0.03159277 | Y38: 0.03159277 | Z38: 0.03159277 | AA38: 0.03159277 | AB38: 0.03159277 | AC38: 0.03159277 | AD38: 0.03159277 | AE38: 0.03159277 | AF38: 0.03159277 | AG38: 0.03159277 | AH38: 0.03159277 | AI38: 0.03159277
A39: 19 | B39: 46023 | C39: 46387 | D39: 46023 | E39: 0 | F39: 46387 | G39: 5.143027 | H39: 1.7494042 | I39: 1.768842 | J39: 1.7882798 | K39: 1.7882798 | L39: 0.64642777 | M39: 0.58387024 | N39: 0.64642777 | O39: 0.62557526 | P39: 0.64642777 | Q39: 0.62557526 | R39: 0.64642777 | S39: 0.64642777 | T39: 0.62557526 | U39: 0.64642777 | V39: 0.62557526 | W39: 0.64642777 | X39: 0.04186847 | Y39: 0.04186847 | Z39: 0.04186847 | AA39: 0.04186847 | AB39: 0.04186847 | AC39: 0.04186847 | AD39: 0.04186847 | AE39: 0.04186847 | AF39: 0.04186847 | AG39: 0.04186847 | AH39: 0.04186847 | AI39: 0.04186847
A40: 19 | B40: 46388 | C40: 2958465 | D40: 46388 | E40: 1 | G40: 4.4181461 | H40: 1.1983465 | I40: 1.2116614 | J40: 1.2249764 | K40: 1.2249764 | L40: 0.45028777 | M40: 0.40671153 | N40: 0.45028777 | O40: 0.43576236 | P40: 0.45028777 | Q40: 0.43576236 | R40: 0.45028777 | S40: 0.45028777 | T40: 0.43576236 | U40: 0.45028777 | V40: 0.43576236 | W40: 0.45028777 | X40: 0.03510308 | Y40: 0.03510308 | Z40: 0.03510308 | AA40: 0.03510308 | AB40: 0.03510308 | AC40: 0.03510308 | AD40: 0.03510308 | AE40: 0.03510308 | AF40: 0.03510308 | AG40: 0.03510308 | AH40: 0.03510308 | AI40: 0.03510308
...

Sheet Rules
A1: TSO code | B1: TSO | C1: Currency | D1: Unit | E1: Currency decimals | F1: Tariff decimals | G1: Equal months: gas year | H1: Equal months: quarter | I1: Hours per unit
A2: AMBERGR | B2: Amber Grid | C2: EUR | D2: kWh/h | E2: 2 | G2: no | H2: no | I2: 24
A3: BGTRGAZ | B3: Bulgartransgaz | C3: EUR | D3: kWh/d | E3: 2 | G3: no | H3: no | I3: 1
A4: DESFA | B4: DESFA | C4: EUR | D4: kWh/h | E4: 2 | G4: no | H4: no | I4: 24
A5: EUSTR | B5: Eustream | C5: EUR | D5: kWh/h | E5: 2 | G5: yes | H5: yes | I5: 24
A6: FGSZ | B6: FGSZ | C6: HUF | D6: kWh/h | E6: 0 | G6: yes | H6: yes | I6: 24
A7: GASCADE | B7: GASCADE | C7: EUR | D7: kWh/h | E7: 2 | G7: no | H7: no | I7: 24
A8: GAZSYS | B8: GAZ-SYSTEM | C8: PLN | D8: kWh/h | E8: 2 | G8: no | H8: no | I8: 24
A9: GCA | B9: Gas Connect Austria | C9: EUR | D9: kWh/h | E9: 2 | F9: 4 | G9: yes | H9: yes | I9: 24
A10: GTS | B10: Gasunie Transport Services | C10: EUR | D10: kWh/h | E10: 2 | G10: no | H10: no | I10: 24
A11: Gastran | B11: Gastrans | C11: EUR | D11: kWh/h | E11: 2 | G11: no | H11: yes | I11: 24
A12: Gasunie | B12: Gasunie Deutschland | C12: EUR | D12: kWh/h | E12: 2 | G12: no | H12: no | I12: 24
A13: ICGB | B13: ICGB | C13: EUR | D13: kWh/d | E13: 2 | G13: no | H13: no | I13: 1
A14: NET4GAS | B14: NET4GAS | C14: CZK | D14: kWh/h | E14: 2 | G14: yes | H14: yes | I14: 24
A15: OGE | B15: Open Grid Europe | C15: EUR | D15: kWh/h | E15: 2 | G15: no | H15: no | I15: 24
A16: Plinovo | B16: Plinovodi | C16: EUR | D16: kWh/h | E16: 2 | G16: no | H16: no | I16: 24
A17: TAG | B17: Trans Austria Gasleitung | C17: EUR | D17: kWh/h | E17: 2 | G17: no | H17: no | I17: 24
A18: TAP | B18: Trans Adriatic Pipeline | C18: EUR | D18: kWh/d | E18: 2 | G18: no | H18: no | I18: 1
A19: TRANSGA | B19: Transgaz | C19: RON | D19: kWh/h | E19: 2 | G19: no | H19: no | I19: 24
A20: UKRTRAG | B20: Gas TSO of Ukraine | C20: EUR | D20: kWh/d | E20: 2 | G20: no | H20: no | I20: 1
A21: plinacr | B21: Plinacro | C21: EUR | D21: kWh/d | E21: 2 | G21: no | H21: no | I21: 1
A22: snam | B22: Snam Rete Gas | C22: EUR | D22: kWh/h | E22: 2 | G22: no | H22: no | I22: 24
